<?xml version="1.0"?>
<sdf version="1.6">
  <model name="diff_drive_robot">
    <static>false</static>

    <link name="base_link">
      <pose>0 0 0.12 0 0 0</pose>
      <inertial>
        <mass>5.0</mass>
        <inertia>
          <ixx>0.08</ixx>
          <ixy>0.0</ixy>
          <ixz>0.0</ixz>
          <iyy>0.10</iyy>
          <iyz>0.0</iyz>
          <izz>0.12</izz>
        </inertia>
      </inertial>
      <collision name="base_collision">
        <geometry>
          <box>
            <size>0.45 0.32 0.16</size>
          </box>
        </geometry>
      </collision>
      <visual name="base_visual">
        <geometry>
          <box>
            <size>0.45 0.32 0.16</size>
          </box>
        </geometry>
        <material>
          <ambient>0.1 0.3 0.8 1</ambient>
          <diffuse>0.1 0.3 0.8 1</diffuse>
        </material>
      </visual>
    </link>

    <link name="imu_link">
      <pose>0 0 0.23 0 0 0</pose>
      <inertial>
        <mass>0.05</mass>
        <inertia>
          <ixx>0.0001</ixx>
          <ixy>0.0</ixy>
          <ixz>0.0</ixz>
          <iyy>0.0001</iyy>
          <iyz>0.0</iyz>
          <izz>0.0001</izz>
        </inertia>
      </inertial>
      <sensor name="imu_sensor" type="imu">
        <always_on>true</always_on>
        <update_rate>100</update_rate>
        <topic>/gazebo/imu_data</topic>
        <imu>
          <angular_velocity>
            <x>
              <noise type="gaussian">
                <mean>0.0</mean>
                <stddev>0.0002</stddev>
              </noise>
            </x>
            <y>
              <noise type="gaussian">
                <mean>0.0</mean>
                <stddev>0.0002</stddev>
              </noise>
            </y>
            <z>
              <noise type="gaussian">
                <mean>0.0</mean>
                <stddev>0.0005</stddev>
              </noise>
            </z>
          </angular_velocity>
          <linear_acceleration>
            <x>
              <noise type="gaussian">
                <mean>0.0</mean>
                <stddev>0.01</stddev>
              </noise>
            </x>
            <y>
              <noise type="gaussian">
                <mean>0.0</mean>
                <stddev>0.01</stddev>
              </noise>
            </y>
            <z>
              <noise type="gaussian">
                <mean>0.0</mean>
                <stddev>0.01</stddev>
              </noise>
            </z>
          </linear_acceleration>
        </imu>
        <plugin name="imu_plugin" filename="libgazebo_ros_imu_sensor.so">
          <ros>
            <namespace>/</namespace>
            <remapping>~/out:=/gazebo/imu_data</remapping>
          </ros>
          <initial_orientation_as_reference>false</initial_orientation_as_reference>
          <frame_name>imu_link</frame_name>
        </plugin>
      </sensor>
    </link>

    <joint name="imu_joint" type="fixed">
      <parent>base_link</parent>
      <child>imu_link</child>
    </joint>

    <link name="left_wheel">
      <pose>0 0.19 0.08 1.57079632679 0 0</pose>
      <inertial>
        <mass>0.5</mass>
        <inertia>
          <ixx>0.002</ixx>
          <ixy>0.0</ixy>
          <ixz>0.0</ixz>
          <iyy>0.002</iyy>
          <iyz>0.0</iyz>
          <izz>0.003</izz>
        </inertia>
      </inertial>
      <collision name="left_wheel_collision">
        <geometry>
          <cylinder>
            <radius>0.08</radius>
            <length>0.04</length>
          </cylinder>
        </geometry>
        <surface>
          <friction>
            <ode>
              <mu>1.0</mu>
              <mu2>1.0</mu2>
            </ode>
          </friction>
        </surface>
      </collision>
      <visual name="left_wheel_visual">
        <geometry>
          <cylinder>
            <radius>0.08</radius>
            <length>0.04</length>
          </cylinder>
        </geometry>
        <material>
          <ambient>0.02 0.02 0.02 1</ambient>
          <diffuse>0.02 0.02 0.02 1</diffuse>
        </material>
      </visual>
    </link>

    <link name="right_wheel">
      <pose>0 -0.19 0.08 1.57079632679 0 0</pose>
      <inertial>
        <mass>0.5</mass>
        <inertia>
          <ixx>0.002</ixx>
          <ixy>0.0</ixy>
          <ixz>0.0</ixz>
          <iyy>0.002</iyy>
          <iyz>0.0</iyz>
          <izz>0.003</izz>
        </inertia>
      </inertial>
      <collision name="right_wheel_collision">
        <geometry>
          <cylinder>
            <radius>0.08</radius>
            <length>0.04</length>
          </cylinder>
        </geometry>
        <surface>
          <friction>
            <ode>
              <mu>1.0</mu>
              <mu2>1.0</mu2>
            </ode>
          </friction>
        </surface>
      </collision>
      <visual name="right_wheel_visual">
        <geometry>
          <cylinder>
            <radius>0.08</radius>
            <length>0.04</length>
          </cylinder>
        </geometry>
        <material>
          <ambient>0.02 0.02 0.02 1</ambient>
          <diffuse>0.02 0.02 0.02 1</diffuse>
        </material>
      </visual>
    </link>

    <link name="caster_wheel">
      <pose>-0.18 0 0.035 0 0 0</pose>
      <inertial>
        <mass>0.1</mass>
        <inertia>
          <ixx>0.0001</ixx>
          <ixy>0.0</ixy>
          <ixz>0.0</ixz>
          <iyy>0.0001</iyy>
          <iyz>0.0</iyz>
          <izz>0.0001</izz>
        </inertia>
      </inertial>
      <collision name="caster_collision">
        <geometry>
          <sphere>
            <radius>0.035</radius>
          </sphere>
        </geometry>
      </collision>
      <visual name="caster_visual">
        <geometry>
          <sphere>
            <radius>0.035</radius>
          </sphere>
        </geometry>
        <material>
          <ambient>0.1 0.1 0.1 1</ambient>
          <diffuse>0.1 0.1 0.1 1</diffuse>
        </material>
      </visual>
    </link>

    <joint name="left_wheel_joint" type="revolute">
      <parent>base_link</parent>
      <child>left_wheel</child>
      <axis>
        <xyz>0 1 0</xyz>
        <limit>
          <lower>-1e16</lower>
          <upper>1e16</upper>
        </limit>
      </axis>
    </joint>

    <joint name="right_wheel_joint" type="revolute">
      <parent>base_link</parent>
      <child>right_wheel</child>
      <axis>
        <xyz>0 1 0</xyz>
        <limit>
          <lower>-1e16</lower>
          <upper>1e16</upper>
        </limit>
      </axis>
    </joint>

    <joint name="caster_joint" type="fixed">
      <parent>base_link</parent>
      <child>caster_wheel</child>
    </joint>

    <plugin name="diff_drive_plugin" filename="libgazebo_ros_diff_drive.so">
      <ros>
        <namespace>/</namespace>
        <remapping>cmd_vel:=/cmd_vel</remapping>
        <remapping>odom:=/gazebo/odom_data</remapping>
      </ros>
      <update_rate>50</update_rate>
      <left_joint>left_wheel_joint</left_joint>
      <right_joint>right_wheel_joint</right_joint>
      <wheel_separation>0.38</wheel_separation>
      <wheel_diameter>0.16</wheel_diameter>
      <max_wheel_torque>20</max_wheel_torque>
      <max_wheel_acceleration>1.0</max_wheel_acceleration>
      <command_topic>/cmd_vel</command_topic>
      <odometry_topic>/gazebo/odom_data</odometry_topic>
      <!-- wheel odometry output -->
      <publish_odom>true</publish_odom>
      <publish_odom_tf>true</publish_odom_tf>
      <publish_wheel_tf>true</publish_wheel_tf>
      <odometry_frame>odom</odometry_frame>
      <robot_base_frame>base_link</robot_base_frame>
    </plugin>
  </model>
</sdf>
